Workbook

Sheet MD Daily
A1: Ticker | B1: Date/Time | C1: Open | D1: High | E1: Low | F1: Close
A2: NIFTYMIDCAP100 | B2: 37622 | C2: 1000 | D2: 1000 | E2: 1000 | F2: 1000
A3: NIFTYMIDCAP100 | B3: 37623 | C3: 1004.74 | D3: 1004.74 | E3: 1004.74 | F3: 1004.74
A4: NIFTYMIDCAP100 | B4: 37624 | C4: 1002.24 | D4: 1002.24 | E4: 1002.24 | F4: 1002.24
A5: NIFTYMIDCAP100 | B5: 37627 | C5: 994.44 | D5: 994.44 | E5: 994.44 | F5: 994.44
A6: NIFTYMIDCAP100 | B6: 37628 | C6: 995.41 | D6: 995.41 | E6: 995.41 | F6: 995.41
A7: NIFTYMIDCAP100 | B7: 37629 | C7: 1010.31 | D7: 1010.31 | E7: 1010.31 | F7: 1010.31
A8: NIFTYMIDCAP100 | B8: 37630 | C8: 1022.53 | D8: 1022.53 | E8: 1022.53 | F8: 1022.53
A9: NIFTYMIDCAP100 | B9: 37631 | C9: 1015.95 | D9: 1015.95 | E9: 1015.95 | F9: 1015.95
A10: NIFTYMIDCAP100 | B10: 37634 | C10: 1016.31 | D10: 1016.31 | E10: 1016.31 | F10: 1016.31
A11: NIFTYMIDCAP100 | B11: 37635 | C11: 1024 | D11: 1024 | E11: 1024 | F11: 1024
A12: NIFTYMIDCAP100 | B12: 37636 | C12: 1030.28 | D12: 1030.28 | E12: 1030.28 | F12: 1030.28
A13: NIFTYMIDCAP100 | B13: 37637 | C13: 1037.15 | D13: 1037.15 | E13: 1037.15 | F13: 1037.15
... A44: NIFTYMIDCAP100 | B44: 37683 | C44: 990.86 | D44: 990.86 | E44: 990.86 | F44: 990.86
A45: NIFTYMIDCAP100 | B45: 37684 | C45: 976.74 | D45: 976.74 | E45: 976.74 | F45: 976.74 | V45: 22223
A46: NIFTYMIDCAP100 | B46: 37685 | C46: 968.96 | D46: 968.96 | E46: 968.96 | F46: 968.96
A47: NIFTYMIDCAP100 | B47: 37686 | C47: 961.05 | D47: 961.05 | E47: 961.05 | F47: 961.05
A48: NIFTYMIDCAP100 | B48: 37687 | C48: 943.29 | D48: 943.29 | E48: 943.29 | F48: 943.29
A49: NIFTYMIDCAP100 | B49: 37690 | C49: 927.76 | D49: 927.76 | E49: 927.76 | F49: 927.76
A50: NIFTYMIDCAP100 | B50: 37691 | C50: 932.78 | D50: 932.78 | E50: 932.78 | F50: 932.78
A51: NIFTYMIDCAP100 | B51: 37692 | C51: 932.57 | D51: 932.57 | E51: 932.57 | F51: 932.57
A52: NIFTYMIDCAP100 | B52: 37693 | C52: 929.05 | D52: 929.05 | E52: 929.05 | F52: 929.05
A53: NIFTYMIDCAP100 | B53: 37697 | C53: 918.05 | D53: 918.05 | E53: 918.05 | F53: 918.05
A54: NIFTYMIDCAP100 | B54: 37699 | C54: 921.56 | D54: 921.56 | E54: 921.56 | F54: 921.56
A55: NIFTYMIDCAP100 | B55: 37700 | C55: 932.74 | D55: 932.74 | E55: 932.74 | F55: 932.74
A56: NIFTYMIDCAP100 | B56: 37701 | C56: 937.93 | D56: 937.93 | E56: 937.93 | F56: 937.93
A57: NIFTYMIDCAP100 | B57: 37702 | C57: 944.77 | D57: 944.77 | E57: 944.77 | F57: 944.77
A58: NIFTYMIDCAP100 | B58: 37704 | C58: 925.7 | D58: 925.7 | E58: 925.7 | F58: 925.7 | V58: =W58-'NF Daily'!F45 -> -152.8 | W58: =MIN('NF Daily'!E45:E58) -> 1503.2 | X58: =W58/'NF Daily'!F45-1 -> -0.092270531
A59: NIFTYMIDCAP100 | B59: 37705 | C59: 920.19 | D59: 920.19 | E59: 920.19 | F59: 920.19
A60: NIFTYMIDCAP100 | B60: 37706 | C60: 919.36 | D60: 919.36 | E60: 919.36 | F60: 919.36
A61: NIFTYMIDCAP100 | B61: 37707 | C61: 917.95 | D61: 917.95 | E61: 917.95 | F61: 917.95
A62: NIFTYMIDCAP100 | B62: 37708 | C62: 917.74 | D62: 917.74 | E62: 917.74 | F62: 917.74
A63: NIFTYMIDCAP100 | B63: 37711 | C63: 894.69 | D63: 894.69 | E63: 894.69 | F63: 894.69
A64: NIFTYMIDCAP100 | B64: 37712 | C64: 903.66 | D64: 903.66 | E64: 903.66 | F64: 903.66
A65: NIFTYMIDCAP100 | B65: 37713 | C65: 920.13 | D65: 920.13 | E65: 920.13 | F65: 920.13
A66: NIFTYMIDCAP100 | B66: 37714 | C66: 934.92 | D66: 934.92 | E66: 934.92 | F66: 934.92
A67: NIFTYMIDCAP100 | B67: 37715 | C67: 952.95 | D67: 952.95 | E67: 952.95 | F67: 952.95
A68: NIFTYMIDCAP100 | B68: 37718 | C68: 975.3 | D68: 975.3 | E68: 975.3 | F68: 975.3
A69: NIFTYMIDCAP100 | B69: 37719 | C69: 977.84 | D69: 977.84 | E69: 977.84 | F69: 977.84
A70: NIFTYMIDCAP100 | B70: 37720 | C70: 968.45 | D70: 968.45 | E70: 968.45 | F70: 968.45
...

Sheet NF Daily
A1: Ticker | B1: Date/Time | C1: Open | D1: High | E1: Low | F1: Close
A2: NIFTY 50 | B2: 36528 | C2: 1482.15 | D2: 1592.9 | E2: 1482.15 | F2: 1592.2 | G2: =TEXT(B2,"dddd") -> Monday | I2: =MONTH(B2) -> 1
A3: NIFTY 50 | B3: 36529 | C3: 1594.4 | D3: 1641.95 | E3: 1594.4 | F3: 1638.7 | G3: =TEXT(B3,"dddd") -> Tuesday | H3: =F3/F2-1 -> 0.029204874 | I3: =MONTH(B3) -> 1
A4: NIFTY 50 | B4: 36530 | C4: 1634.55 | D4: 1635.5 | E4: 1555.05 | F4: 1595.8 | G4: =TEXT(B4,"dddd") -> Wednesday | H4: =F4/F3-1 -> -0.026179288 | I4: =MONTH(B4) -> 1
A5: NIFTY 50 | B5: 36531 | C5: 1595.8 | D5: 1639 | E5: 1595.8 | F5: 1617.6 | G5: =TEXT(B5,"dddd") -> Thursday | H5: =F5/F4-1 -> 0.01366086 | I5: =MONTH(B5) -> 1
A6: NIFTY 50 | B6: 36532 | C6: 1616.6 | D6: 1628.25 | E6: 1597.2 | F6: 1613.3 | G6: =TEXT(B6,"dddd") -> Friday | H6: =F6/F5-1 -> -0.0026582591 | I6: =MONTH(B6) -> 1
A7: NIFTY 50 | B7: 36535 | C7: 1615.65 | D7: 1662.1 | E7: 1614.95 | F7: 1632.95 | G7: =TEXT(B7,"dddd") -> Monday | H7: =F7/F6-1 -> 0.012180004 | I7: =MONTH(B7) -> 1
A8: NIFTY 50 | B8: 36536 | C8: 1633.25 | D8: 1639.9 | E8: 1548.25 | F8: 1572.5 | G8: =TEXT(B8,"dddd") -> Tuesday | H8: =F8/F7-1 -> -0.037018892 | I8: =MONTH(B8) -> 1
A9: NIFTY 50 | B9: 36537 | C9: 1572.3 | D9: 1631.55 | E9: 1571.7 | F9: 1624.8 | G9: =TEXT(B9,"dddd") -> Wednesday | H9: =F9/F8-1 -> 0.033259141 | I9: =MONTH(B9) -> 1
A10: NIFTY 50 | B10: 36538 | C10: 1627.85 | D10: 1671.15 | E10: 1613.65 | F10: 1621.4 | G10: =TEXT(B10,"dddd") -> Thursday | H10: =F10/F9-1 -> -0.0020925652 | I10: =MONTH(B10) -> 1
A11: NIFTY 50 | B11: 36539 | C11: 1622.15 | D11: 1627.4 | E11: 1591.4 | F11: 1622.75 | G11: =TEXT(B11,"dddd") -> Friday | H11: =F11/F10-1 -> 0.00083261379 | I11: =MONTH(B11) -> 1
A12: NIFTY 50 | B12: 36542 | C12: 1623.5 | D12: 1668.45 | E12: 1604.65 | F12: 1611.6 | G12: =TEXT(B12,"dddd") -> Monday | H12: =F12/F11-1 -> -0.0068710522 | I12: =MONTH(B12) -> 1
A13: NIFTY 50 | B13: 36543 | C13: 1611.65 | D13: 1615.15 | E13: 1587.85 | F13: 1606.7 | G13: =TEXT(B13,"dddd") -> Tuesday | H13: =F13/F12-1 -> -0.0030404567 | I13: =MONTH(B13) -> 1
A14: NIFTY 50 | B14: 36544 | C14: 1610.05 | D14: 1644.45 | E14: 1608.85 | F14: 1634.85 | G14: =TEXT(B14,"dddd") -> Wednesday | H14: =F14/F13-1 -> 0.017520383 | I14: =MONTH(B14) -> 1
... A5970: NIFTY 50 | B5970: 45292 | C5970: 21727.75 | D5970: 21834.35 | E5970: 21680.85 | F5970: 21741.9 | G5970: =TEXT(B5970,"dddd") -> Monday | H5970: =F5970/F5969-1 -> 0.00048317182 | I5970: =MONTH(B5970) -> 1
A5971: NIFTY 50 | B5971: 45293 | C5971: 21751.35 | D5971: 21755.6 | E5971: 21555.65 | F5971: 21665.8 | G5971: =TEXT(B5971,"dddd") -> Tuesday | H5971: =F5971/F5970-1 -> -0.0035001541 | I5971: =MONTH(B5971) -> 1 | M5971: -0.009110673
A5972: NIFTY 50 | B5972: 45294 | C5972: 21661.1 | D5972: 21677 | E5972: 21500.35 | F5972: 21517.35 | G5972: =TEXT(B5972,"dddd") -> Wednesday | H5972: =F5972/F5971-1 -> -0.0068518125 | I5972: =MONTH(B5972) -> 1 | M5972: 0.0092671464
A5973: NIFTY 50 | B5973: 45295 | C5973: 21605.8 | D5973: 21685.65 | E5973: 21564.55 | F5973: 21658.6 | G5973: =TEXT(B5973,"dddd") -> Thursday | H5973: =F5973/F5972-1 -> 0.0065644701 | I5973: =MONTH(B5973) -> 1 | M5973: 0.018030591
A5974: NIFTY 50 | B5974: 45296 | C5974: 21705.75 | D5974: 21749.6 | E5974: 21629.2 | F5974: 21710.8 | G5974: =TEXT(B5974,"dddd") -> Friday | H5974: =F5974/F5973-1 -> 0.0024101281 | I5974: =MONTH(B5974) -> 1 | M5974: -0.0037567837
A5975: NIFTY 50 | B5975: 45299 | C5975: 21747.6 | D5975: 21763.95 | E5975: 21492.9 | F5975: 21513 | G5975: =TEXT(B5975,"dddd") -> Monday | H5975: =F5975/F5974-1 -> -0.009110673 | I5975: =MONTH(B5975) -> 1
A5976: NIFTY 50 | B5976: 45300 | C5976: 21653.6 | D5976: 21724.45 | E5976: 21517.85 | F5976: 21544.85 | G5976: =TEXT(B5976,"dddd") -> Tuesday | H5976: =F5976/F5975-1 -> 0.0014805002 | I5976: =MONTH(B5976) -> 1 | M5976: 0.0036999732
A5977: NIFTY 50 | B5977: 45301 | C5977: 21529.3 | D5977: 21641.85 | E5977: 21448.65 | F5977: 21618.7 | G5977: =TEXT(B5977,"dddd") -> Wednesday | H5977: =F5977/F5976-1 -> 0.0034277333 | I5977: =MONTH(B5977) -> 1 | M5977: -0.0040809987
A5978: NIFTY 50 | B5978: 45302 | C5978: 21688 | D5978: 21726.5 | E5978: 21593.75 | F5978: 21647.2 | G5978: =TEXT(B5978,"dddd") -> Thursday | H5978: =F5978/F5977-1 -> 0.0013183031 | I5978: =MONTH(B5978) -> 1 | M5978: 0.0012154578
A5979: NIFTY 50 | B5979: 45303 | C5979: 21773.55 | D5979: 21928.25 | E5979: 21715.15 | F5979: 21894.55 | G5979: =TEXT(B5979,"dddd") -> Friday | H5979: =F5979/F5978-1 -> 0.01142642 | I5979: =MONTH(B5979) -> 1 | M5979: -0.0071531617
A5980: NIFTY 50 | B5980: 45306 | C5980: 22053.15 | D5980: 22115.55 | E5980: 21963.55 | F5980: 22097.45 | G5980: =TEXT(B5980,"dddd") -> Monday | H5980: =F5980/F5979-1 -> 0.0092671464 | I5980: =MONTH(B5980) -> 1
A5981: NIFTY 50 | B5981: 45307 | C5981: 22080.5 | D5981: 22124.15 | E5981: 21969.8 | F5981: 22032.3 | G5981: =TEXT(B5981,"dddd") -> Tuesday | H5981: =F5981/F5980-1 -> -0.002948304 | I5981: =MONTH(B5981) -> 1 | M5981: 0.0060509968
A5982: NIFTY 50 | B5982: 45308 | C5982: 21647.25 | D5982: 21851.5 | E5982: 21550.45 | F5982: 21571.95 | G5982: =TEXT(B5982,"dddd") -> Wednesday | H5982: =F5982/F5981-1 -> -0.020894323 | I5982: =MONTH(B5982) -> 1 | M5982: 0.0067780951
A5983: NIFTY 50 | B5983: 45309 | C5983: 21414.2 | D5983: 21539.4 | E5983: 21285.55 | F5983: 21462.25 | G5983: =TEXT(B5983,"dddd") -> Thursday | H5983: =F5983/F5982-1 -> -0.0050853075 | I5983: =MONTH(B5983) -> 1 | M5983: -0.01096388
A5984: NIFTY 50 | B5984: 45310 | C5984: 21615.2 | D5984: 21670.6 | E5984: 21575 | F5984: 21622.4 | G5984: =TEXT(B5984,"dddd") -> Friday | H5984: =F5984/F5983-1 -> 0.007461939 | I5984: =MONTH(B5984) -> 1 | M5984: 0.0085519483
A5985: NIFTY 50 | B5985: 45311 | C5985: 21706.15 | D5985: 21720.3 | E5985: 21541.8 | F5985: 21571.8 | G5985: =TEXT(B5985,"dddd") -> Saturday | H5985: =F5985/F5984-1 -> -0.0023401658 | I5985: =MONTH(B5985) -> 1 | M5985: 0.00996657
A5986: NIFTY 50 | B5986: 45314 | C5986: 21716.7 | D5986: 21750.25 | E5986: 21192.6 | F5986: 21238.8 | G5986: =TEXT(B5986,"dddd") -> Tuesday | H5986: =F5986/F5985-1 -> -0.01543682 | I5986: =MONTH(B5986) -> 1 | M5986: -0.0014749164
A5987: NIFTY 50 | B5987: 45315 | C5987: 21185.25 | D5987: 21482.35 | E5987: 21137.2 | F5987: 21453.95 | G5987: =TEXT(B5987,"dddd") -> Wednesday | H5987: =F5987/F5986-1 -> 0.010130045 | I5987: =MONTH(B5987) -> 1 | M5987: 0.0022148972
A5988: NIFTY 50 | B5988: 45316 | C5988: 21454.6 | D5988: 21459 | E5988: 21247.05 | F5988: 21352.6 | G5988: =TEXT(B5988,"dddd") -> Thursday | H5988: =F5988/F5987-1 -> -0.0047240718 | I5988: =MONTH(B5988) -> 1 | M5988: -0.0010737419
A5989: NIFTY 50 | B5989: 45320 | C5989: 21433.1 | D5989: 21763.25 | E5989: 21429.6 | F5989: 21737.6 | G5989: =TEXT(B5989,"dddd") -> Monday | H5989: =F5989/F5988-1 -> 0.018030591 | I5989: =MONTH(B5989) -> 1
A5990: NIFTY 50 | B5990: 45321 | C5990: 21775.75 | D5990: 21813.05 | E5990: 21501.8 | F5990: 21522.1 | G5990: =TEXT(B5990,"dddd") -> Tuesday | H5990: =F5990/F5989-1 -> -0.0099136979 | I5990: =MONTH(B5990) -> 1 | M5990: -0.001328888
A5991: NIFTY 50 | B5991: 45322 | C5991: 21487.25 | D5991: 21741.35 | E5991: 21448.85 | F5991: 21725.7 | G5991: =TEXT(B5991,"dddd") -> Wednesday | H5991: =F5991/F5990-1 -> 0.0094600434 | I5991: =MONTH(B5991) -> 1 | M5991: 0.0015637566
A5992: NIFTY 50 | B5992: 45323 | C5992: 21780.65 | D5992: 21832.95 | E5992: 21658.75 | F5992: 21697.45 | G5992: =TEXT(B5992,"dddd") -> Thursday | H5992: =F5992/F5991-1 -> -0.0013003033 | I5992: =MONTH(B5992) -> 2 | M5992: 0.0054705005
A5993: NIFTY 50 | B5993: 45324 | C5993: 21812.75 | D5993: 22126.8 | E5993: 21805.55 | F5993: 21853.8 | G5993: =TEXT(B5993,"dddd") -> Friday | H5993: =F5993/F5992-1 -> 0.0072059159 | I5993: =MONTH(B5993) -> 2 | M5993: -0.00013566931
A5994: NIFTY 50 | B5994: 45327 | C5994: 21921.05 | D5994: 21964.3 | E5994: 21726.95 | F5994: 21771.7 | G5994: =TEXT(B5994,"dddd") -> Monday | H5994: =F5994/F5993-1 -> -0.0037567837 | I5994: =MONTH(B5994) -> 2
A5995: NIFTY 50 | B5995: 45328 | C5995: 21825.2 | D5995: 21951.4 | E5995: 21737.55 | F5995: 21929.4 | G5995: =TEXT(B5995,"dddd") -> Tuesday | H5995: =F5995/F5994-1 -> 0.007243348 | I5995: =MONTH(B5995) -> 2 | M5995: -0.00088256036
...

Sheet Sheet4
A2: 45292 | B2: 21741.9 | D2: 1
A3: 45299 | B3: 21513 | C3: =B3/B2-1 -> -0.010528059 | D3: =D2+C3 -> 0.98947194
A4: 45306 | B4: 22097.45 | C4: =B4/B3-1 -> 0.027167294 | D4: =D3+C4 -> 1.0166392
A5: 45320 | B5: 21737.6 | C5: =B5/B4-1 -> -0.016284684 | D5: =D4+C5 -> 1.0003546
A6: 45327 | B6: 21771.7 | C6: =B6/B5-1 -> 0.0015687104 | D6: =D5+C6 -> 1.0019233
A7: 45334 | B7: 21616.05 | C7: =B7/B6-1 -> -0.0071491891 | D7: =D6+C7 -> 0.99477407
A8: 45341 | B8: 22122.25 | C8: =B8/B7-1 -> 0.023417784 | D8: =D7+C8 -> 1.0181919
A9: 45348 | B9: 22122.05 | C9: =B9/B8-1 -> -9.0406717e-06 | D9: =D8+C9 -> 1.0181828
A10: 45355 | B10: 22405.6 | C10: =B10/B9-1 -> 0.012817528 | D10: =D9+C10 -> 1.0310003
A11: 45362 | B11: 22332.65 | C11: =B11/B10-1 -> -0.0032558825 | D11: =D10+C11 -> 1.0277445
A12: 45369 | B12: 22055.7 | C12: =B12/B11-1 -> -0.012401126 | D12: =D11+C12 -> 1.0153433
A13: 45383 | B13: 22462 | C13: =B13/B12-1 -> 0.018421542 | D13: =D12+C13 -> 1.0337649
A14: 45390 | B14: 22666.3 | C14: =B14/B13-1 -> 0.0090953611 | D14: =D13+C14 -> 1.0428602
... A50: 45656 | B50: 23644.9 | C50: =B50/B49-1 -> -0.0045698625 | D50: =D49+C50 -> 1.0912469

Sheet Sheet2
A1: …..
A2: 0.024846725
A3: 0.016178018
A4: 0.0050218789
A5: -0.024524884
A6: 0.0045865135
A7: -0.019665774
A8: -0.0069621148
A9: 0.056383096
A10: 0.0060488834
A11: 0.0018145021
A12: -0.021199655
A13: 0.010795572
... A638: 0.0073538341

Sheet BNF Daily
A1: Ticker | B1: Date/Time | C1: Open | D1: High | E1: Low | F1: Close
A2: NIFTYBANK | B2: 36528 | C2: 1054.81 | D2: 1054.81 | E2: 1054.81 | F2: 1054.81
A3: NIFTYBANK | B3: 36529 | C3: 1092.08 | D3: 1092.08 | E3: 1092.08 | F3: 1092.08
A4: NIFTYBANK | B4: 36530 | C4: 1055.99 | D4: 1055.99 | E4: 1055.99 | F4: 1055.99
A5: NIFTYBANK | B5: 36531 | C5: 1086.67 | D5: 1086.67 | E5: 1086.67 | F5: 1086.67
A6: NIFTYBANK | B6: 36532 | C6: 1126.99 | D6: 1126.99 | E6: 1126.99 | F6: 1126.99
A7: NIFTYBANK | B7: 36535 | C7: 1088.97 | D7: 1088.97 | E7: 1088.97 | F7: 1088.97
A8: NIFTYBANK | B8: 36536 | C8: 1033.55 | D8: 1033.55 | E8: 1033.55 | F8: 1033.55
A9: NIFTYBANK | B9: 36537 | C9: 1036.63 | D9: 1036.63 | E9: 1036.63 | F9: 1036.63
A10: NIFTYBANK | B10: 36538 | C10: 1034.19 | D10: 1034.19 | E10: 1034.19 | F10: 1034.19
A11: NIFTYBANK | B11: 36539 | C11: 1023.41 | D11: 1023.41 | E11: 1023.41 | F11: 1023.41
A12: NIFTYBANK | B12: 36542 | C12: 1035.99 | D12: 1035.99 | E12: 1035.99 | F12: 1035.99
A13: NIFTYBANK | B13: 36543 | C13: 1021.69 | D13: 1021.69 | E13: 1021.69 | F13: 1021.69
... A6536: NIFTYBANK | B6536: 46127 | C6536: 56343.45 | D6536: 56786.25 | E6536: 56109.2 | F6536: 56301.95

Sheet BNF Weekly
A1: Ticker | B1: Date/Time | C1: Open | D1: High | E1: Low | F1: Close
A2: NIFTYBANK | B2: 36532 | C2: 1054.81 | D2: 1126.99 | E2: 1054.81 | F2: 1126.99
A3: NIFTYBANK | B3: 36539 | C3: 1088.97 | D3: 1088.97 | E3: 1023.41 | F3: 1023.41
A4: NIFTYBANK | B4: 36546 | C4: 1035.99 | D4: 1058.91 | E4: 1021.69 | F4: 1058.91
A5: NIFTYBANK | B5: 36553 | C5: 1049.82 | D5: 1153.35 | E5: 1049.82 | F5: 1153.35
A6: NIFTYBANK | B6: 36560 | C6: 1148.89 | D6: 1186.97 | E6: 1148.89 | F6: 1172.21
A7: NIFTYBANK | B7: 36567 | C7: 1158.08 | D7: 1181.48 | E7: 1150.2 | F7: 1156.67
A8: NIFTYBANK | B8: 36574 | C8: 1212.66 | D8: 1212.66 | E8: 1148.1 | F8: 1151.56
A9: NIFTYBANK | B9: 36581 | C9: 1142.8 | D9: 1142.8 | E9: 1091.48 | F9: 1109.38
A10: NIFTYBANK | B10: 36588 | C10: 1141.18 | D10: 1141.18 | E10: 1075.15 | F10: 1124.7
A11: NIFTYBANK | B11: 36595 | C11: 1126.59 | D11: 1126.59 | E11: 987.88 | F11: 987.88
A12: NIFTYBANK | B12: 36601 | C12: 978.64 | D12: 1055.36 | E12: 978.64 | F12: 1055.36
A13: NIFTYBANK | B13: 36609 | C13: 1074.75 | D13: 1088.21 | E13: 1074.75 | F13: 1086.32
... A1373: NIFTYBANK | B1373: 46127 | C1373: 54646 | D1373: 56786.25 | E1373: 54356.2 | F1373: 56301.95

Sheet MD Weekly
A1: Ticker | B1: Date/Time | C1: Open | D1: High | E1: Low | F1: Close
A2: NIFTYMIDCAP100 | B2: 37624 | C2: 1000 | D2: 1004.74 | E2: 1000 | F2: 1002.24 | G2: =WEEKNUM(B2) -> 1
A3: NIFTYMIDCAP100 | B3: 37631 | C3: 994.44 | D3: 1022.53 | E3: 994.44 | F3: 1015.95 | G3: =WEEKNUM(B3) -> 2
A4: NIFTYMIDCAP100 | B4: 37638 | C4: 1016.31 | D4: 1037.15 | E4: 1016.31 | F4: 1035.38 | G4: =WEEKNUM(B4) -> 3
A5: NIFTYMIDCAP100 | B5: 37645 | C5: 1035.83 | D5: 1042.81 | E5: 1004.62 | F5: 1004.62 | G5: =WEEKNUM(B5) -> 4
A6: NIFTYMIDCAP100 | B6: 37652 | C6: 974.52 | D6: 990.55 | E6: 974.52 | F6: 981.1 | G6: =WEEKNUM(B6) -> 5
A7: NIFTYMIDCAP100 | B7: 37659 | C7: 997.44 | D7: 998.74 | E7: 990.79 | F7: 998.74 | G7: =WEEKNUM(B7) -> 6
A8: NIFTYMIDCAP100 | B8: 37666 | C8: 979.34 | D8: 979.34 | E8: 955.2 | F8: 955.2 | G8: =WEEKNUM(B8) -> 7
A9: NIFTYMIDCAP100 | B9: 37673 | C9: 983.92 | D9: 994.69 | E9: 983.92 | F9: 992.21 | G9: =WEEKNUM(B9) -> 8
A10: NIFTYMIDCAP100 | B10: 37680 | C10: 998.79 | D10: 998.79 | E10: 981.45 | F10: 991.76 | G10: =WEEKNUM(B10) -> 9
A11: NIFTYMIDCAP100 | B11: 37687 | C11: 990.86 | D11: 990.86 | E11: 943.29 | F11: 943.29 | G11: =WEEKNUM(B11) -> 10
A12: NIFTYMIDCAP100 | B12: 37693 | C12: 927.76 | D12: 932.78 | E12: 927.76 | F12: 929.05 | G12: =WEEKNUM(B12) -> 11
A13: NIFTYMIDCAP100 | B13: 37702 | C13: 918.05 | D13: 944.77 | E13: 918.05 | F13: 944.77 | G13: =WEEKNUM(B13) -> 12
... A1217: NIFTYMIDCAP100 | B1217: 46127 | C1217: 56676.4 | D1217: 58850.25 | E1217: 56289.5 | F1217: 58777.75 | G1217: =WEEKNUM(B1217) -> 16

Sheet NF Weekly
A1: Ticker | B1: Date/Time | C1: Open | D1: High | E1: Low | F1: Close | G1: Week Number | H1: % CHANGE | I1: YTD | J1: FILTER | K1: Week num | L1: Month | M1: Year
A2: NIFTY 50 | B2: 36532 | C2: 1482.15 | D2: 1641.95 | E2: 1482.15 | F2: 1613.3 | G2: =WEEKNUM(B2) -> 2 | H2: 0 | J2: 0 | K2: =WEEKNUM(B2) -> 2 | L2: =MONTH(B2) -> 1 | M2: =YEAR(B2) -> 2000 | O2: 1 | P2: =AVERAGEIF($G$2:$G$1357,$G$54,$H$2:$H$1357) -> 0.017444741 | Q2: =AVERAGEIF($G$2:$G$1357,$G$54,$H$2:$H$1357) -> 0.017444741
A3: NIFTY 50 | B3: 36539 | C3: 1615.65 | D3: 1671.15 | E3: 1548.25 | F3: 1622.75 | G3: =WEEKNUM(B3) -> 3 | H3: =F3/F2-1 -> 0.005857559 | I3: =(1+H2)*(1+H3)-1 -> 0.005857559 | J3: =H3>10% -> FALSE | K3: =WEEKNUM(B3) -> 3 | L3: =MONTH(B3) -> 1 | M3: =YEAR(B3) -> 2000 | O3: =O2+1 -> 2 | P3: =AVERAGEIF($G$2:$G$1357,$G$55,$H$2:$H$1357) -> -0.0053032944 | Q3: =(1+P3)*(1+Q2)-1 -> 0.012048932
A4: NIFTY 50 | B4: 36546 | C4: 1623.5 | D4: 1668.45 | E4: 1587.85 | F4: 1620.6 | G4: =WEEKNUM(B4) -> 4 | H4: =F4/F3-1 -> -0.0013249114 | I4: =(1+I3)*(1+H4)-1 -> 0.0045248869 | J4: =H4>10% -> FALSE | K4: =WEEKNUM(B4) -> 4 | L4: =MONTH(B4) -> 1 | M4: =YEAR(B4) -> 2000 | O4: =O3+1 -> 3 | P4: =AVERAGEIF($G$2:$G$1357,$G$3,$H$2:$H$1357) -> -0.00072001938 | Q4: =(1+P4)*(1+Q3)-1 -> 0.011320237
A5: NIFTY 50 | B5: 36553 | C5: 1623.05 | D5: 1645 | E5: 1579.55 | F5: 1599.1 | G5: =WEEKNUM(B5) -> 5 | H5: =F5/F4-1 -> -0.013266691 | I5: =(1+I4)*(1+H5)-1 -> -0.0088018347 | J5: =H5>10% -> FALSE | K5: =WEEKNUM(B5) -> 5 | L5: =MONTH(B5) -> 1 | M5: =YEAR(B5) -> 2000 | O5: =O4+1 -> 4 | P5: =AVERAGEIF($G$2:$G$1357,$G$4,$H$2:$H$1357) -> -0.004608227 | Q5: =(1+P5)*(1+Q4)-1 -> 0.006659844
A6: NIFTY 50 | B6: 36560 | C6: 1598.35 | D6: 1621.35 | E6: 1521.4 | F6: 1599.75 | G6: =WEEKNUM(B6) -> 6 | H6: =F6/F5-1 -> 0.00040647864 | I6: =(1+I5)*(1+H6)-1 -> -0.0083989339 | J6: =H6>10% -> FALSE | K6: =WEEKNUM(B6) -> 6 | L6: =MONTH(B6) -> 2 | M6: =YEAR(B6) -> 2000 | O6: =O5+1 -> 5 | P6: =AVERAGEIF($G$2:$G$1357,$G$5,$H$2:$H$1357) -> -0.0032669902 | Q6: =(1+P6)*(1+Q5)-1 -> 0.0033710961
A7: NIFTY 50 | B7: 36567 | C7: 1599.8 | D7: 1771.65 | E7: 1599.8 | F7: 1756 | G7: =WEEKNUM(B7) -> 7 | H7: =F7/F6-1 -> 0.097671511 | I7: =(1+I6)*(1+H7)-1 -> 0.088452241 | J7: =H7>10% -> FALSE | K7: =WEEKNUM(B7) -> 7 | L7: =MONTH(B7) -> 2 | M7: =YEAR(B7) -> 2000 | O7: =O6+1 -> 6 | P7: =AVERAGEIF($G$2:$G$1357,$G$6,$H$2:$H$1357) -> 0.006143188 | Q7: =(1+P7)*(1+Q6)-1 -> 0.0095349934
A8: NIFTY 50 | B8: 36574 | C8: 1777.75 | D8: 1795.45 | E8: 1694.45 | F8: 1717.8 | G8: =WEEKNUM(B8) -> 8 | H8: =F8/F7-1 -> -0.021753986 | I8: =(1+I7)*(1+H8)-1 -> 0.064774066 | J8: =H8>10% -> FALSE | K8: =WEEKNUM(B8) -> 8 | L8: =MONTH(B8) -> 2 | M8: =YEAR(B8) -> 2000 | O8: =O7+1 -> 7 | P8: =AVERAGEIF($G$2:$G$1357,$G$7,$H$2:$H$1357) -> 0.0055331788 | Q8: =(1+P8)*(1+Q7)-1 -> 0.015120931
A9: NIFTY 50 | B9: 36581 | C9: 1719.55 | D9: 1818.15 | E9: 1689.2 | F9: 1710.45 | G9: =WEEKNUM(B9) -> 9 | H9: =F9/F8-1 -> -0.0042787286 | I9: =(1+I8)*(1+H9)-1 -> 0.060218186 | J9: =H9>10% -> FALSE | K9: =WEEKNUM(B9) -> 9 | L9: =MONTH(B9) -> 2 | M9: =YEAR(B9) -> 2000 | O9: =O8+1 -> 8 | P9: =AVERAGEIF($G$2:$G$1357,$G$8,$H$2:$H$1357) -> -0.006922478 | Q9: =(1+P9)*(1+Q8)-1 -> 0.0080937787
A10: NIFTY 50 | B10: 36588 | C10: 1711.15 | D10: 1783.3 | E10: 1626.35 | F10: 1656 | G10: =WEEKNUM(B10) -> 10 | H10: =F10/F9-1 -> -0.031833728 | I10: =(1+I9)*(1+H10)-1 -> 0.026467489 | J10: =H10>10% -> FALSE | K10: =WEEKNUM(B10) -> 10 | L10: =MONTH(B10) -> 3 | M10: =YEAR(B10) -> 2000 | O10: =O9+1 -> 9 | P10: =AVERAGEIF($G$2:$G$1357,$G$9,$H$2:$H$1357) -> -0.0084824561 | Q10: =(1+P10)*(1+Q9)-1 -> -0.00045733248
A11: NIFTY 50 | B11: 36595 | C11: 1656 | D11: 1765.25 | E11: 1588.2 | F11: 1602.75 | G11: =WEEKNUM(B11) -> 11 | H11: =F11/F10-1 -> -0.032155797 | I11: =(1+I10)*(1+H11)-1 -> -0.0065393913 | J11: =H11>10% -> FALSE | K11: =WEEKNUM(B11) -> 11 | L11: =MONTH(B11) -> 3 | M11: =YEAR(B11) -> 2000 | O11: =O10+1 -> 10 | P11: =AVERAGEIF($G$2:$G$1357,$G$10,$H$2:$H$1357) -> 0.0023769803 | Q11: =(1+P11)*(1+Q10)-1 -> 0.0019185608
A12: NIFTY 50 | B12: 36601 | C12: 1601.4 | D12: 1645 | E12: 1503.2 | F12: 1562.2 | G12: =WEEKNUM(B12) -> 12 | H12: =F12/F11-1 -> -0.025300265 | I12: =(1+I11)*(1+H12)-1 -> -0.031674208 | J12: =H12>10% -> FALSE | K12: =WEEKNUM(B12) -> 12 | L12: =MONTH(B12) -> 3 | M12: =YEAR(B12) -> 2000 | O12: =O11+1 -> 11 | P12: =AVERAGEIF($G$2:$G$1357,$G$11,$H$2:$H$1357) -> -0.0088041721 | Q12: =(1+P12)*(1+Q11)-1 -> -0.0069025027
A13: NIFTY 50 | B13: 36609 | C13: 1563.3 | D13: 1629.2 | E13: 1540.45 | F13: 1569.55 | G13: =WEEKNUM(B13) -> 13 | H13: =F13/F12-1 -> 0.0047049033 | I13: =(1+I12)*(1+H13)-1 -> -0.027118329 | J13: =H13>10% -> FALSE | K13: =WEEKNUM(B13) -> 13 | L13: =MONTH(B13) -> 3 | M13: =YEAR(B13) -> 2000 | O13: =O12+1 -> 12 | P13: =AVERAGEIF($G$2:$G$1357,$G$12,$H$2:$H$1357) -> -0.005713363 | Q13: =(1+P13)*(1+Q12)-1 -> -0.012576429
A14: NIFTY 50 | B14: 36616 | C14: 1570.45 | D14: 1609.4 | E14: 1489.1 | F14: 1528.45 | G14: =WEEKNUM(B14) -> 14 | H14: =F14/F13-1 -> -0.026185849 | I14: =(1+I13)*(1+H14)-1 -> -0.052594062 | J14: =H14>10% -> FALSE | K14: =WEEKNUM(B14) -> 14 | L14: =MONTH(B14) -> 3 | M14: =YEAR(B14) -> 2000 | O14: =O13+1 -> 13 | P14: =AVERAGEIF($G$2:$G$1357,$G$13,$H$2:$H$1357) -> 0.0099817976 | Q14: =(1+P14)*(1+Q13)-1 -> -0.0027201669
A15: NIFTY 50 | B15: 36623 | C15: 1528.7 | D15: 1558.05 | E15: 1381.05 | F15: 1557.15 | G15: =WEEKNUM(B15) -> 15 | H15: =F15/F14-1 -> 0.018777193 | I15: =(1+I14)*(1+H15)-1 -> -0.034804438 | J15: =H15>10% -> FALSE | K15: =WEEKNUM(B15) -> 15 | L15: =MONTH(B15) -> 4 | M15: =YEAR(B15) -> 2000 | O15: =O14+1 -> 14 | P15: =AVERAGEIF($G$2:$G$1357,$G$14,$H$2:$H$1357) -> 0.0038033704 | Q15: =(1+P15)*(1+Q14)-1 -> 0.0010728577
A16: NIFTY 50 | B16: 36629 | C16: 1557.55 | D16: 1636.95 | E16: 1502.7 | F16: 1518.65 | G16: =WEEKNUM(B16) -> 16 | H16: =F16/F15-1 -> -0.024724657 | I16: =(1+I15)*(1+H16)-1 -> -0.058668568 | J16: =H16>10% -> FALSE | K16: =WEEKNUM(B16) -> 16 | L16: =MONTH(B16) -> 4 | M16: =YEAR(B16) -> 2000 | O16: =O15+1 -> 15 | P16: =AVERAGEIF($G$2:$G$1357,$G$15,$H$2:$H$1357) -> 0.0030674588 | Q16: =(1+P16)*(1+Q15)-1 -> 0.0041436074
A17: NIFTY 50 | B17: 36636 | C17: 1518.55 | D17: 1518.55 | E17: 1339.75 | F17: 1415.65 | G17: =WEEKNUM(B17) -> 17 | H17: =F17/F16-1 -> -0.067823396 | I17: =(1+I16)*(1+H17)-1 -> -0.12251286 | J17: =H17>10% -> FALSE | K17: =WEEKNUM(B17) -> 17 | L17: =MONTH(B17) -> 4 | M17: =YEAR(B17) -> 2000 | O17: =O16+1 -> 16 | P17: =AVERAGEIF($G$2:$G$1357,$G$16,$H$2:$H$1357) -> 0.0095970906 | Q17: =(1+P17)*(1+Q16)-1 -> 0.013780465
A18: NIFTY 50 | B18: 36644 | C18: 1416.05 | D18: 1455.85 | E18: 1311.3 | F18: 1406.55 | G18: =WEEKNUM(B18) -> 18 | H18: =F18/F17-1 -> -0.0064281425 | I18: =(1+I17)*(1+H18)-1 -> -0.12815347 | J18: =H18>10% -> FALSE | K18: =WEEKNUM(B18) -> 18 | L18: =MONTH(B18) -> 4 | M18: =YEAR(B18) -> 2000 | O18: =O17+1 -> 17 | P18: =AVERAGEIF($G$2:$G$1357,$G$17,$H$2:$H$1357) -> -0.0012443578 | Q18: =(1+P18)*(1+Q17)-1 -> 0.012518959
A19: NIFTY 50 | B19: 36651 | C19: 1410 | D19: 1428.6 | E19: 1258.1 | F19: 1422.4 | G19: =WEEKNUM(B19) -> 19 | H19: =F19/F18-1 -> 0.011268707 | I19: =(1+I18)*(1+H19)-1 -> -0.11832889 | J19: =H19>10% -> FALSE | K19: =WEEKNUM(B19) -> 19 | L19: =MONTH(B19) -> 5 | M19: =YEAR(B19) -> 2000
A20: NIFTY 50 | B20: 36658 | C20: 1423.25 | D20: 1436.6 | E20: 1276.4 | F20: 1282.8 | G20: =WEEKNUM(B20) -> 20 | H20: =F20/F19-1 -> -0.098143982 | I20: =(1+I19)*(1+H20)-1 -> -0.2048596 | J20: =H20>10% -> FALSE | K20: =WEEKNUM(B20) -> 20 | L20: =MONTH(B20) -> 5 | M20: =YEAR(B20) -> 2000
A21: NIFTY 50 | B21: 36665 | C21: 1281.3 | D21: 1347.7 | E21: 1220.7 | F21: 1268 | G21: =WEEKNUM(B21) -> 21 | H21: =F21/F20-1 -> -0.011537262 | I21: =(1+I20)*(1+H21)-1 -> -0.21403335 | J21: =H21>10% -> FALSE | K21: =WEEKNUM(B21) -> 21 | L21: =MONTH(B21) -> 5 | M21: =YEAR(B21) -> 2000
A22: NIFTY 50 | B22: 36672 | C22: 1267.85 | D22: 1278.75 | E22: 1201.5 | F22: 1275.35 | G22: =WEEKNUM(B22) -> 22 | H22: =F22/F21-1 -> 0.00579653 | I22: =(1+I21)*(1+H22)-1 -> -0.20947747 | J22: =H22>10% -> FALSE | K22: =WEEKNUM(B22) -> 22 | L22: =MONTH(B22) -> 5 | M22: =YEAR(B22) -> 2000
A23: NIFTY 50 | B23: 36679 | C23: 1273.7 | D23: 1410.75 | E23: 1267.4 | F23: 1389.25 | G23: =WEEKNUM(B23) -> 23 | H23: =F23/F22-1 -> 0.089308817 | I23: =(1+I22)*(1+H23)-1 -> -0.13887684 | J23: =H23>10% -> FALSE | K23: =WEEKNUM(B23) -> 23 | L23: =MONTH(B23) -> 6 | M23: =YEAR(B23) -> 2000
A24: NIFTY 50 | B24: 36686 | C24: 1390.95 | D24: 1485.5 | E24: 1390.95 | F24: 1467.2 | G24: =WEEKNUM(B24) -> 24 | H24: =F24/F23-1 -> 0.056109412 | I24: =(1+I23)*(1+H24)-1 -> -0.090559722 | J24: =H24>10% -> FALSE | K24: =WEEKNUM(B24) -> 24 | L24: =MONTH(B24) -> 6 | M24: =YEAR(B24) -> 2000
A25: NIFTY 50 | B25: 36693 | C25: 1464.4 | D25: 1480.85 | E25: 1411.9 | F25: 1477.3 | G25: =WEEKNUM(B25) -> 25 | H25: =F25/F24-1 -> 0.0068838604 | I25: =(1+I24)*(1+H25)-1 -> -0.084299262 | J25: =H25>10% -> FALSE | K25: =WEEKNUM(B25) -> 25 | L25: =MONTH(B25) -> 6 | M25: =YEAR(B25) -> 2000
A26: NIFTY 50 | B26: 36700 | C26: 1477.55 | D26: 1539.1 | E26: 1461.3 | F26: 1472.2 | G26: =WEEKNUM(B26) -> 26 | H26: =F26/F25-1 -> -0.003452244 | I26: =(1+I25)*(1+H26)-1 -> -0.087460485 | J26: =H26>10% -> FALSE | K26: =WEEKNUM(B26) -> 26 | L26: =MONTH(B26) -> 6 | M26: =YEAR(B26) -> 2000
A27: NIFTY 50 | B27: 36707 | C27: 1472.15 | D27: 1505.75 | E27: 1431.25 | F27: 1471.45 | G27: =WEEKNUM(B27) -> 27 | H27: =F27/F26-1 -> -0.00050944165 | I27: =(1+I26)*(1+H27)-1 -> -0.08792537 | J27: =H27>10% -> FALSE | K27: =WEEKNUM(B27) -> 27 | L27: =MONTH(B27) -> 6 | M27: =YEAR(B27) -> 2000
A28: NIFTY 50 | B28: 36714 | C28: 1473.45 | D28: 1530.9 | E28: 1473.45 | F28: 1517.6 | G28: =WEEKNUM(B28) -> 28 | H28: =F28/F27-1 -> 0.031363621 | I28: =(1+I27)*(1+H28)-1 -> -0.059319407 | J28: =H28>10% -> FALSE | K28: =WEEKNUM(B28) -> 28 | L28: =MONTH(B28) -> 7 | M28: =YEAR(B28) -> 2000
A29: NIFTY 50 | B29: 36721 | C29: 1518.15 | D29: 1564.75 | E29: 1502.7 | F29: 1509.75 | G29: =WEEKNUM(B29) -> 29 | H29: =F29/F28-1 -> -0.005172641 | I29: =(1+I28)*(1+H29)-1 -> -0.06418521 | J29: =H29>10% -> FALSE | K29: =WEEKNUM(B29) -> 29 | L29: =MONTH(B29) -> 7 | M29: =YEAR(B29) -> 2000
A30: NIFTY 50 | B30: 36728 | C30: 1509.25 | D30: 1512.25 | E30: 1394.3 | F30: 1397.25 | G30: =WEEKNUM(B30) -> 30 | H30: =F30/F29-1 -> -0.074515648 | I30: =(1+I29)*(1+H30)-1 -> -0.13391806 | J30: =H30>10% -> FALSE | K30: =WEEKNUM(B30) -> 30 | L30: =MONTH(B30) -> 7 | M30: =YEAR(B30) -> 2000
... A111: NIFTY 50 | B111: 37295 | C111: 1083.05 | D111: 1131.85 | E111: 1069.4 | F111: 1123.75 | G111: =WEEKNUM(B111) -> 6 | H111: =F111/F110-1 -> 0.038922017 | I111: =(1+I110)*(1+H111)-1 -> -0.30344635 | J111: =H111>10% -> FALSE | K111: =WEEKNUM(B111) -> 6 | L111: =MONTH(B111) -> 2 | M111: =YEAR(B111) -> 2002
A112: NIFTY 50 | B112: 37302 | C112: 1124.85 | D112: 1164.1 | E112: 1124.85 | F112: 1159.95 | G112: =WEEKNUM(B112) -> 7 | H112: =F112/F111-1 -> 0.032213571 | I112: =(1+I111)*(1+H112)-1 -> -0.28100787 | J112: =H112>10% -> FALSE | K112: =WEEKNUM(B112) -> 7 | L112: =MONTH(B112) -> 2 | M112: =YEAR(B112) -> 2002 | N112: =F112/F60-1 -> -0.16027799
A113: NIFTY 50 | B113: 37309 | C113: 1159.85 | D113: 1178.1 | E113: 1134.65 | F113: 1163.5 | G113: =WEEKNUM(B113) -> 8 | H113: =F113/F112-1 -> 0.0030604767 | I113: =(1+I112)*(1+H113)-1 -> -0.27880741 | J113: =H113>10% -> FALSE | K113: =WEEKNUM(B113) -> 8 | L113: =MONTH(B113) -> 2 | M113: =YEAR(B113) -> 2002
A114: NIFTY 50 | B114: 37316 | C114: 1163.65 | D114: 1205.95 | E114: 1135.2 | F114: 1178 | G114: =WEEKNUM(B114) -> 9 | H114: =F114/F113-1 -> 0.012462398 | I114: =(1+I113)*(1+H114)-1 -> -0.26981962 | J114: =H114>10% -> FALSE | K114: =WEEKNUM(B114) -> 9 | L114: =MONTH(B114) -> 3 | M114: =YEAR(B114) -> 2002
A115: NIFTY 50 | B115: 37323 | C115: 1178.45 | D115: 1201.1 | E115: 1162.75 | F115: 1187.65 | G115: =WEEKNUM(B115) -> 10 | H115: =F115/F114-1 -> 0.0081918506 | I115: =(1+I114)*(1+H115)-1 -> -0.2638381 | J115: =H115>10% -> FALSE | K115: =WEEKNUM(B115) -> 10 | L115: =MONTH(B115) -> 3 | M115: =YEAR(B115) -> 2002
A116: NIFTY 50 | B116: 37330 | C116: 1187.5 | D116: 1192.75 | E116: 1143.55 | F116: 1169.75 | G116: =WEEKNUM(B116) -> 11 | H116: =F116/F115-1 -> -0.01507178 | I116: =(1+I115)*(1+H116)-1 -> -0.27493337 | J116: =H116>10% -> FALSE | K116: =WEEKNUM(B116) -> 11 | L116: =MONTH(B116) -> 3 | M116: =YEAR(B116) -> 2002
A117: NIFTY 50 | B117: 37337 | C117: 1169.95 | D117: 1184.7 | E117: 1135.9 | F117: 1138.45 | G117: =WEEKNUM(B117) -> 12 | H117: =F117/F116-1 -> -0.026757854 | I117: =(1+I116)*(1+H117)-1 -> -0.29433459 | J117: =H117>10% -> FALSE | K117: =WEEKNUM(B117) -> 12 | L117: =MONTH(B117) -> 3 | M117: =YEAR(B117) -> 2002
A118: NIFTY 50 | B118: 37343 | C118: 1138.1 | D118: 1140.2 | E118: 1117.85 | F118: 1129.55 | G118: =WEEKNUM(B118) -> 13 | H118: =F118/F117-1 -> -0.0078176468 | I118: =(1+I117)*(1+H118)-1 -> -0.29985124 | J118: =H118>10% -> FALSE | K118: =WEEKNUM(B118) -> 13 | L118: =MONTH(B118) -> 3 | M118: =YEAR(B118) -> 2002
A119: NIFTY 50 | B119: 37351 | C119: 1129.85 | D119: 1153.3 | E119: 1121.45 | F119: 1141.95 | G119: =WEEKNUM(B119) -> 14 | H119: =F119/F118-1 -> 0.010977823 | I119: =(1+I118)*(1+H119)-1 -> -0.29216513 | J119: =H119>10% -> FALSE | K119: =WEEKNUM(B119) -> 14 | L119: =MONTH(B119) -> 4 | M119: =YEAR(B119) -> 2002
A120: NIFTY 50 | B120: 37358 | C120: 1141.9 | D120: 1151.55 | E120: 1122.1 | F120: 1146.5 | G120: =WEEKNUM(B120) -> 15 | H120: =F120/F119-1 -> 0.0039844126 | I120: =(1+I119)*(1+H120)-1 -> -0.28934482 | J120: =H120>10% -> FALSE | K120: =WEEKNUM(B120) -> 15 | L120: =MONTH(B120) -> 4 | M120: =YEAR(B120) -> 2002
...

Sheet Sheet3
A1: Date | B1: % change | C1: Week number | F1: Date | G1: % change | J1: Week number
A2: 36532 | B2: 0 | C2: 2 | F2: 36636 | G2: -0.067823396 | H2: 1415.65 | M2: 18065
A3: 36539 | B3: 0.005857559 | C3: 3 | F3: 37008 | G3: -0.037325175 | H3: 1101.3 | I3: =H3-H2/H2*100 -> 1001.3 | J3: =INDEX('NF Weekly'!$B$2:$B$1373,MATCH(Sheet3!$F3,'NF Weekly'!$B$2:$B$1373,1))-365 -> 36643 | K3: =VLOOKUP(J3,'NF Weekly'!$B$2:$F$1373,6,0) -> #N/A | M3: 22419.95 | N3: =M3/M2-1 -> 0.24107113
A4: 36546 | B4: -0.0013249114 | C4: 4 | F4: 37372 | G4: -0.0026356448 | H4: 1097.4 | I4: =H4-H3/H3*100 -> 997.4 | J4: =INDEX('NF Weekly'!$B$2:$B$1373,MATCH(Sheet3!$F4,'NF Weekly'!$B$2:$B$1373,1))-365 -> 37007 | K4: =VLOOKUP(J4,'NF Weekly'!$B$2:$F$1373,6,0) -> #N/A | M4: 24039.35 | N4: =M4/M3-1 -> 0.072230313
A5: 36553 | B5: -0.013266691 | C5: 5 | F5: 37736 | G5: -0.017433826 | H5: 924.3 | I5: =H5-H4/H4*100 -> 824.3 | J5: =INDEX('NF Weekly'!$B$2:$B$1373,MATCH(Sheet3!$F5,'NF Weekly'!$B$2:$B$1373,1))-365 -> 37371 | K5: =VLOOKUP(J5,'NF Weekly'!$B$2:$F$1373,6,0) -> #N/A
A6: 36560 | B6: 0.00040647864 | C6: 6 | F6: 38100 | G6: 0.013034634 | H6: 1892.45 | I6: =H6-H5/H5*100 -> 1792.45 | J6: =INDEX('NF Weekly'!$B$2:$B$1373,MATCH(Sheet3!$F6,'NF Weekly'!$B$2:$B$1373,1))-365 -> 37735 | K6: =VLOOKUP(J6,'NF Weekly'!$B$2:$F$1373,6,0) -> #N/A
A7: 36567 | B7: 0.097671511 | C7: 7 | F7: 38464 | G7: 0.0056484179 | H7: 1967.35 | I7: =H7-H6/H6*100 -> 1867.35 | J7: =INDEX('NF Weekly'!$B$2:$B$1373,MATCH(Sheet3!$F7,'NF Weekly'!$B$2:$B$1373,1))-365 -> 38099 | K7: =VLOOKUP(J7,'NF Weekly'!$B$2:$F$1373,6,0) -> #N/A
A8: 36574 | B8: -0.021753986 | C8: 8 | F8: 38836 | G8: -0.0043240369 | H8: 3557.6 | I8: =H8-H7/H7*100 -> 3457.6 | J8: =INDEX('NF Weekly'!$B$2:$B$1373,MATCH(Sheet3!$F8,'NF Weekly'!$B$2:$B$1373,1))-365 -> 38471 | K8: =VLOOKUP(J8,'NF Weekly'!$B$2:$F$1373,6,0) -> #REF!
A9: 36581 | B9: -0.0042787286 | C9: 9 | F9: 39199 | G9: -1.2244248e-05 | H9: 4083.5 | I9: =H9-H8/H8*100 -> 3983.5 | J9: =INDEX('NF Weekly'!$B$2:$B$1373,MATCH(Sheet3!$F9,'NF Weekly'!$B$2:$B$1373,1))-365 -> 38834 | K9: =VLOOKUP(J9,'NF Weekly'!$B$2:$F$1373,6,0) -> #N/A
A10: 36588 | B10: -0.031833728 | C10: 10 | F10: 39563 | G10: 0.030917231 | H10: 5111.7 | I10: =H10-H9/H9*100 -> 5011.7 | J10: =INDEX('NF Weekly'!$B$2:$B$1373,MATCH(Sheet3!$F10,'NF Weekly'!$B$2:$B$1373,1))-365 -> 39198 | K10: =VLOOKUP(J10,'NF Weekly'!$B$2:$F$1373,6,0) -> #N/A
A11: 36595 | B11: -0.032155797 | C11: 11 | F11: 39927 | G11: 0.028468857 | H11: 3480.75 | I11: =H11-H10/H10*100 -> 3380.75 | J11: =INDEX('NF Weekly'!$B$2:$B$1373,MATCH(Sheet3!$F11,'NF Weekly'!$B$2:$B$1373,1))-365 -> 39562 | K11: =VLOOKUP(J11,'NF Weekly'!$B$2:$F$1373,6,0) -> #N/A
A12: 36601 | B12: -0.025300265 | C12: 12 | F12: 40291 | G12: 0.0078858359 | H12: 5304.1 | I12: =H12-H11/H11*100 -> 5204.1 | J12: =INDEX('NF Weekly'!$B$2:$B$1373,MATCH(Sheet3!$F12,'NF Weekly'!$B$2:$B$1373,1))-365 -> 39926 | K12: =VLOOKUP(J12,'NF Weekly'!$B$2:$F$1373,6,0) -> #N/A
A13: 36609 | B13: 0.0047049033 | C13: 13 | F13: 40654 | G13: 0.010326978 | H13: 5884.7 | I13: =H13-H12/H12*100 -> 5784.7 | J13: =INDEX('NF Weekly'!$B$2:$B$1373,MATCH(Sheet3!$F13,'NF Weekly'!$B$2:$B$1373,1))-365 -> 40289 | K13: =VLOOKUP(J13,'NF Weekly'!$B$2:$F$1373,6,0) -> #N/A
A14: 36616 | B14: -0.026185849 | C14: 14 | F14: 41027 | G14: -0.015470104 | H14: 5209 | I14: =H14-H13/H13*100 -> 5109 | J14: =INDEX('NF Weekly'!$B$2:$B$1373,MATCH(Sheet3!$F14,'NF Weekly'!$B$2:$B$1373,1))-365 -> 40662 | K14: =VLOOKUP(J14,'NF Weekly'!$B$2:$F$1373,6,0) -> #REF!
A15: 36623 | B15: 0.018777193 | C15: 15 | F15: 41390 | G15: 0.015277273 | H15: 5871.45 | I15: =H15-H14/H14*100 -> 5771.45 | J15: =INDEX('NF Weekly'!$B$2:$B$1373,MATCH(Sheet3!$F15,'NF Weekly'!$B$2:$B$1373,1))-365 -> 41025 | K15: =VLOOKUP(J15,'NF Weekly'!$B$2:$F$1373,6,0) -> #N/A
A16: 36629 | B16: -0.024724657 | C16: 16 | F16: 41754 | G16: 0.00049414402 | H16: 6782.75 | I16: =H16-H15/H15*100 -> 6682.75 | J16: =INDEX('NF Weekly'!$B$2:$B$1373,MATCH(Sheet3!$F16,'NF Weekly'!$B$2:$B$1373,1))-365 -> 41389 | K16: =VLOOKUP(J16,'NF Weekly'!$B$2:$F$1373,6,0) -> #N/A
... A27: 36959 | B27: -0.039499368 | C27: 10 | F27: 45772 | G27: 0.0078694765 | H27: 24039.35 | I27: =H27-H26/H26*100 -> 23939.35 | J27: =INDEX('NF Weekly'!$B$2:$B$1373,MATCH(Sheet3!$F27,'NF Weekly'!$B$2:$B$1373,1))-365 -> 45407 | K27: =VLOOKUP(J27,'NF Weekly'!$B$2:$F$1373,6,0) -> #N/A
A28: 36966 | B28: -0.048774656 | C28: 11
A29: 36973 | B29: -0.027020234 | C29: 12
A30: 36980 | B30: -0.011280462 | C30: 13
A31: 36987 | B31: -0.0074899843 | C31: 14
A32: 36993 | B32: -0.10064935 | C32: 15
A33: 37001 | B33: 0.11620646 | C33: 16
A34: 37008 | B34: -0.037325175 | C34: 17
A35: 37260 | B35: 0.060359837 | C35: 1
A36: 37267 | B36: -0.0069786535 | C36: 2
A37: 37274 | B37: 0.004225805 | C37: 3
A38: 37281 | B38: -0.011937977 | C38: 4
A39: 37288 | B39: 0.0014350523 | C39: 5
... A438: 45772 | B438: 0.0078694765 | C438: 17
C439: 1
C440: 2
C441: 3
C442: 4
C443: 6
C444: 6
C445: 7
C446: 8
C447: 9
C448: 10
...

Sheet Sheet1
A2: 36636 | B2: -0.067823396 | C2: =B2*100 -> -6.7823396 | D2: -0.067823396 | E2: =D2+F2 -> 0.9321766 | F2: 1 | G2: =(E2*100)-1 -> 92.21766
A3: 37008 | B3: -0.037325175 | D3: -0.037325175 | E3: =D3+F3 -> 0.96267483 | F3: 1 | G3: =E3*100 -> 96.267483
A4: 37372 | B4: -0.0026356448 | D4: -0.0026356448 | E4: =D4+F4 -> 0.99736436 | F4: 1 | G4: =E4*100 -> 99.736436
A5: 37736 | B5: -0.017433826 | D5: -0.017433826 | E5: =D5+F5 -> 0.98256617 | F5: 1 | G5: =E5*100 -> 98.256617
A6: 38100 | B6: 0.013034634 | D6: 0.013034634 | E6: =D6+F6 -> 1.0130346 | F6: 1 | G6: =E6*100 -> 101.30346
A7: 38464 | B7: 0.0056484179 | D7: 0.0056484179 | E7: =D7+F7 -> 1.0056484 | F7: 1 | G7: =E7*100 -> 100.56484
A8: 38836 | B8: -0.0043240369 | D8: -0.0043240369 | E8: =D8+F8 -> 0.99567596 | F8: 1 | G8: =E8*100 -> 99.567596
A9: 39199 | B9: -1.2244248e-05 | D9: -1.2244248e-05 | E9: =D9+F9 -> 0.99998776 | F9: 1 | G9: =E9*100 -> 99.998776
A10: 39563 | B10: 0.030917231 | D10: 0.030917231 | E10: =D10+F10 -> 1.0309172 | F10: 1 | G10: =E10*100 -> 103.09172
A11: 39927 | B11: 0.028468857 | D11: 0.028468857 | E11: =D11+F11 -> 1.0284689 | F11: 1 | G11: =E11*100 -> 102.84689
A12: 40291 | B12: 0.0078858359 | D12: 0.0078858359 | E12: =D12+F12 -> 1.0078858 | F12: 1 | G12: =E12*100 -> 100.78858
A13: 40654 | B13: 0.010326978 | D13: 0.010326978 | E13: =D13+F13 -> 1.010327 | F13: 1 | G13: =E13*100 -> 101.0327
A14: 41027 | B14: -0.015470104 | D14: -0.015470104 | E14: =D14+F14 -> 0.9845299 | F14: 1 | G14: =E14*100 -> 98.45299
... A27: 45772 | B27: 0.0078694765 | D27: 0.0078694765 | E27: =D27+F27 -> 1.0078695 | F27: 1 | G27: =E27*100 -> 100.78695

Sheet NF_Monthly
A1: Ticker | B1: Date/Time | C1: Open | D1: High | E1: Low | F1: Close
A2: NIFTY 50 | B2: 36556 | C2: 1482.15 | D2: 1671.15 | E2: 1482.15 | F2: 1546.2
A3: NIFTY 50 | B3: 36585 | C3: 1546.2 | D3: 1818.15 | E3: 1521.4 | F3: 1654.8
A4: NIFTY 50 | B4: 36616 | C4: 1661.5 | D4: 1773.85 | E4: 1489.1 | F4: 1528.45
A5: NIFTY 50 | B5: 36644 | C5: 1528.7 | D5: 1636.95 | E5: 1311.3 | F5: 1406.55
A6: NIFTY 50 | B6: 36677 | C6: 1410 | D6: 1436.6 | E6: 1201.5 | F6: 1380.45
A7: NIFTY 50 | B7: 36707 | C7: 1380.4 | D7: 1539.1 | E7: 1345.1 | F7: 1471.45
A8: NIFTY 50 | B8: 36738 | C8: 1473.45 | D8: 1564.75 | E8: 1269.25 | F8: 1332.85
A9: NIFTY 50 | B9: 36769 | C9: 1332.85 | D9: 1398.9 | E9: 1295.45 | F9: 1394.1
A10: NIFTY 50 | B10: 36798 | C10: 1395.95 | D10: 1482 | E10: 1249.35 | F10: 1271.65
A11: NIFTY 50 | B11: 36830 | C11: 1270.75 | D11: 1306.45 | E11: 1108.2 | F11: 1172.75
A12: NIFTY 50 | B12: 36860 | C12: 1178.25 | D12: 1281 | E12: 1177.1 | F12: 1268.15
A13: NIFTY 50 | B13: 36889 | C13: 1268.1 | D13: 1369.5 | E13: 1207.95 | F13: 1263.55
... A317: NIFTY 50 | B317: 46127 | C317: 22899 | D317: 24280.9 | E317: 22182.55 | F317: 24231.3

Sheet MD_Monthly
A1: Ticker | B1: Date/Time | C1: Open | D1: High | E1: Low | F1: Close
A2: NIFTYMIDCAP100 | B2: 37652 | C2: 1000 | D2: 1042.81 | E2: 974.52 | F2: 981.1
A3: NIFTYMIDCAP100 | B3: 37680 | C3: 997.44 | D3: 998.79 | E3: 955.2 | F3: 991.76
A4: NIFTYMIDCAP100 | B4: 37711 | C4: 990.86 | D4: 990.86 | E4: 894.69 | F4: 894.69
A5: NIFTYMIDCAP100 | B5: 37741 | C5: 903.66 | D5: 977.84 | E5: 903.66 | F5: 956.94
A6: NIFTYMIDCAP100 | B6: 37771 | C6: 981.9 | D6: 1169.91 | E6: 981.9 | F6: 1169.91
A7: NIFTYMIDCAP100 | B7: 37802 | C7: 1166.4 | D7: 1288.17 | E7: 1166.4 | F7: 1288.17
A8: NIFTYMIDCAP100 | B8: 37833 | C8: 1298.02 | D8: 1402 | E8: 1295.93 | F8: 1399.19
A9: NIFTYMIDCAP100 | B9: 37862 | C9: 1411.19 | D9: 1597.36 | E9: 1410.27 | F9: 1597.36
A10: NIFTYMIDCAP100 | B10: 37894 | C10: 1615.99 | D10: 1664.34 | E10: 1555.43 | F10: 1662.89
A11: NIFTYMIDCAP100 | B11: 37925 | C11: 1678.7 | D11: 1813.57 | E11: 1678.7 | F11: 1774.27
A12: NIFTYMIDCAP100 | B12: 37953 | C12: 1792.64 | D12: 1961.65 | E12: 1792.64 | F12: 1961.65
A13: NIFTYMIDCAP100 | B13: 37986 | C13: 2009.43 | D13: 2422.06 | E13: 2009.43 | F13: 2388.4
... A281: NIFTYMIDCAP100 | B281: 46127 | C281: 54075.45 | D281: 58850.25 | E281: 52032.85 | F281: 58777.75

Sheet BNF_Monthly
A1: Ticker | B1: Date/Time | C1: Open | D1: High | E1: Low | F1: Close
A2: NIFTYBANK | B2: 36556 | C2: 1054.81 | D2: 1153.35 | E2: 1021.69 | F2: 1148.89
A3: NIFTYBANK | B3: 36585 | C3: 1175.15 | D3: 1212.66 | E3: 1075.15 | F3: 1075.15
A4: NIFTYBANK | B4: 36616 | C4: 1139.88 | D4: 1141.08 | E4: 978.64 | F4: 1106.83
A5: NIFTYBANK | B5: 36644 | C5: 1110.14 | D5: 1110.14 | E5: 989.2 | F5: 1056.2
A6: NIFTYBANK | B6: 36677 | C6: 1021.98 | D6: 1040.91 | E6: 948.48 | F6: 1001.24
A7: NIFTYBANK | B7: 36707 | C7: 985.93 | D7: 1120.48 | E7: 985.93 | F7: 1087.18
A8: NIFTYBANK | B8: 36738 | C8: 1119.29 | D8: 1135.06 | E8: 983.99 | F8: 993.58
A9: NIFTYBANK | B9: 36769 | C9: 979.73 | D9: 1017.43 | E9: 975.52 | F9: 1003.07
A10: NIFTYBANK | B10: 36798 | C10: 1015.61 | D10: 1044.64 | E10: 901.51 | F10: 907.53
A11: NIFTYBANK | B11: 36830 | C11: 892.85 | D11: 892.85 | E11: 829.96 | F11: 861.27
A12: NIFTYBANK | B12: 36860 | C12: 885.52 | D12: 958.16 | E12: 878.06 | F12: 941.08
A13: NIFTYBANK | B13: 36889 | C13: 946.47 | D13: 1018.01 | E13: 925.84 | F13: 971.73
... A102: NIFTYBANK | B102: 39598 | C102: 7774.1 | D102: 7990.45 | E102: 6502.45 | F102: 6584.35
A103: NIFTYBANK | B103: 39629 | C103: 6577.3 | D103: 6677.15 | E103: 4996.85 | F103: 5027.05 | G103: 0
A104: NIFTYBANK | B104: 39660 | C104: 5042.1 | D104: 6468.4 | E104: 4633.95 | F104: 5730.05
A105: NIFTYBANK | B105: 39689 | C105: 5655.35 | D105: 6754.45 | E105: 5546.9 | F105: 6102.05
A106: NIFTYBANK | B106: 39721 | C106: 6070.9 | D106: 6631.95 | E106: 5296.6 | F106: 5803.55
A107: NIFTYBANK | B107: 39752 | C107: 5875.55 | D107: 6040.15 | E107: 3799.35 | F107: 4521.7
A108: NIFTYBANK | B108: 39780 | C108: 4791.8 | D108: 5431.9 | E108: 3972.15 | F108: 4291.15
A109: NIFTYBANK | B109: 39813 | C109: 4317.8 | D109: 5226.85 | E109: 3919 | F109: 5001.55
A110: NIFTYBANK | B110: 39843 | C110: 5019.2 | D110: 5448.8 | E110: 4049.9 | F110: 4456.55
A111: NIFTYBANK | B111: 39871 | C111: 4403.9 | D111: 4602.15 | E111: 3758.4 | F111: 3892.4
A112: NIFTYBANK | B112: 39903 | C112: 3831.25 | D112: 4423.65 | E112: 3314.55 | F112: 4133.2
A113: NIFTYBANK | B113: 39932 | C113: 4153.55 | D113: 5288.7 | E113: 4023.45 | F113: 5130.95
A114: NIFTYBANK | B114: 39962 | C114: 5291.25 | D114: 7567.9 | E114: 5291.25 | F114: 7416
A115: NIFTYBANK | B115: 39994 | C115: 7559.3 | D115: 7626.95 | E115: 6909.5 | F115: 7338.85
... A143: NIFTYBANK | B143: 40847 | C143: 9332.6 | D143: 10080.05 | E143: 8626.45 | F143: 9989.65
A144: NIFTYBANK | B144: 40877 | C144: 9898.4 | D144: 9984.35 | E144: 8240.45 | F144: 8564.1 | G144: 0
A145: NIFTYBANK | B145: 40907 | C145: 8872.8 | D145: 9273.1 | E145: 7766.35 | F145: 7968.65
A146: NIFTYBANK | B146: 40939 | C146: 8009.85 | D146: 9969.25 | E146: 7888.25 | F146: 9919.45
A147: NIFTYBANK | B147: 40968 | C147: 9941.9 | D147: 11226.75 | E147: 9762 | F147: 10414.2
A148: NIFTYBANK | B148: 40998 | C148: 10385.15 | D148: 10912.05 | E148: 9845.4 | F148: 10212.75
A149: NIFTYBANK | B149: 41029 | C149: 10186.8 | D149: 10645.85 | E149: 10029.45 | F149: 10276.8
A150: NIFTYBANK | B150: 41060 | C150: 10282.7 | D150: 10382.35 | E150: 8995.25 | F150: 9441
A151: NIFTYBANK | B151: 41089 | C151: 9434.45 | D151: 10360 | E151: 9110.45 | F151: 10340.65
A152: NIFTYBANK | B152: 41121 | C152: 10366.5 | D152: 10782.55 | E152: 10056.15 | F152: 10384.1
A153: NIFTYBANK | B153: 41152 | C153: 10347.8 | D153: 10640.75 | E153: 9948.7 | F153: 9990.5
A154: NIFTYBANK | B154: 41180 | C154: 10030.85 | D154: 11536.85 | E154: 9814.05 | F154: 11456.8
A155: NIFTYBANK | B155: 41213 | C155: 11462.1 | D155: 11745.2 | E155: 10043.6 | F155: 11268.8
...
